<mujoco model="double_pendulum">
    option timestep="0.001 gravity="0 0 -9.81"  <!-- Normal gravity -->

    <worldbody>
        <!-- 🔹 Fixed Pivot (Anchor Point) -->
        <body name="pivot" pos="0 0 1">
            <geom type="sphere" size="0.05" rgba="0.2 0.2 0.2 1"/>  <!-- Small pivot sphere -->

            <!-- 🔹 First Arm (Connected to Pivot) -->
            <body name="pendulum1" pos="0 0 -0.3">
                <joint name="joint1" type="hinge" axis="0 1 0" range="-180 180" damping="0.01"/>  
                <geom type="capsule" fromto="0 0 0 0 0 -0.3" size="0.03" rgba="0 1 0 1" mass="1"/>  

                <!-- 🔹 Second Arm (Connected to First Arm) -->
                <body name="pendulum2" pos="0 0 -0.3">
                    <joint name="joint2" type="hinge" axis="0 1 0" range="-180 180" damping="0.01"/>  
                    <geom type="capsule" fromto="0 0 0 0 0 -0.3" size="0.03" rgba="0 0 1 1" mass="1"/>  
                </body>
            </body>
        </body>
    </worldbody>
</mujoco>

